Workbook

Sheet Summary
A1: Odometer Photo Audit
A2: Source file: APISCLAIMReport-1792688442-1ea3879.csv | Run: 23-Oct-2026 07:33 | App version 1.0.0
A3: A photo is compliant only if a date/time AND a location (address or lat/long) are printed on it. Results were read automatically from the photos (offline); check marked photos in Photo Review column V before sending.
A5: Photos
A6: Odometer photos in file | B6: =COUNTA('Photo Review'!A2:A403)
A7: Timestamp + Location | B7: =COUNTIF('Photo Review'!W2:W403,"Timestamp + Location")
A8: Timestamp only (no location) | B8: =COUNTIF('Photo Review'!W2:W403,"Timestamp only (no location)")
A9: Location only (no timestamp) | B9: =COUNTIF('Photo Review'!W2:W403,"Location only (no timestamp)")
A10: No stamp | B10: =COUNTIF('Photo Review'!W2:W403,"No stamp")
A11: No stamp - gallery screenshot | B11: =COUNTIF('Photo Review'!W2:W403,"No stamp - gallery screenshot")
A12: Photo missing / not downloaded | B12: =COUNTIF('Photo Review'!W2:W403,"Photo missing / not downloaded")
A13: Photos NOT compliant | B13: =COUNTIF('Photo Review'!X2:X403,"No")
A14: Photos with a red flag | B14: =COUNTIF('Photo Review'!S2:S403,"?*")
A16: Claims
A17: Odometer claims | B17: =COUNTA('Claim Review'!A2:A202)
A18: Compliant claims | B18: =COUNTIF('Claim Review'!M2:M202,"Compliant")
A19: NON-COMPLIANT claims | B19: =COUNTIF('Claim Review'!M2:M202,"NON-COMPLIANT")
A20: Amount on non-compliant claims (₹) | B20: =SUMIF('Claim Review'!M2:M202,"NON-COMPLIANT",'Claim Review'!J2:J202)
A21: Total odometer claim amount (₹) | B21: =SUM('Claim Review'!J2:J202)
A23: Employees
A24: Employees | B24: =COUNTA('Employee Summary'!A2:A80)
A25: No stamp on any photo | B25: =COUNTIF('Employee Summary'!O2:O80,"No stamp on any photo")
A26: Some photos without stamp | B26: =COUNTIF('Employee Summary'!O2:O80,"Some photos without stamp")
A27: Compliant | B27: =COUNTIF('Employee Summary'!O2:O80,"Compliant")
A28: Employees with at least one non-compliant photo | B28: =B25+B26
A29: Employees with a High red flag | B29: =COUNTIF('Employee Summary'!N2:N80,">0")
A31: Red flags (see Red Flags sheet)
A32: High priority findings | B32: =COUNTIF('Red Flags'!A2:A39,"High")
A33: Medium priority findings | B33: =COUNTIF('Red Flags'!A2:A39,"Medium")
A34: Low priority findings | B34: =COUNTIF('Red Flags'!A2:A39,"Low")
A36: HR verification before sending
A37: Photos marked for HR check (Photo Review column U) | B37: =COUNTIF('Photo Review'!U2:U403,"?*")
A38: Checked so far | B38: =COUNTIFS('Photo Review'!U2:U403,"?*",'Photo Review'!V2:V403,"?*")
A39: Still to check | B39: =B37-B38
A40: Results found WRONG by HR | B40: =COUNTIF('Photo Review'!V2:V403,"Wrong*")
A41: Random-sample results found wrong | B41: =COUNTIFS('Photo Review'!U2:U403,"3*",'Photo Review'!V2:V403,"Wrong*")
A43: Run details
A44: Claim rows with odometer photos | B44: 201
A45: Photo links | B45: 402
A46: Photos downloaded / read | B46: 402
...

Sheet Employee Summary
A1: Employee_code | B1: User_Name | C1: Designation | D1: Zone | E1: HQ | F1: L1 Approver | G1: Odometer Claims | H1: Photos | I1: Photos with Timestamp + Location | J1: Photos NOT Compliant | K1: Non-Compliant Claims | L1: Amount on Non-Compliant Claims (₹) | M1: Total Odometer Claim Amount (₹) | N1: High Red Flags | O1: Employee Status | P1: Red Flags (photos)
A2: SL04418 | B2: P SHIVA PRASAD YADAV | C2: SR | D2: GTR07 | E2: Sri Kalahasti | F2: VINOD KANDAPPAGARI | G2: =COUNTIF('Claim Review'!$B$2:$B$202,A2) | H2: =COUNTIF('Photo Review'!$B$2:$B$403,A2) | I2: =COUNTIFS('Photo Review'!$B$2:$B$403,A2,'Photo Review'!$X$2:$X$403,"Yes") | J2: =H2-I2 | K2: =COUNTIFS('Claim Review'!$B$2:$B$202,A2,'Claim Review'!$M$2:$M$202,"NON-COMPLIANT") | L2: =SUMIFS('Claim Review'!$J$2:$J$202,'Claim Review'!$B$2:$B$202,A2,'Claim Review'!$M$2:$M$202,"NON-COMPLIANT") | M2: =SUMIFS('Claim Review'!$J$2:$J$202,'Claim Review'!$B$2:$B$202,A2) | N2: =COUNTIFS('Photo Review'!$B$2:$B$403,A2,'Photo Review'!$T$2:$T$403,"High") | O2: =IF(I2=0,"No stamp on any photo",IF(J2>0,"Some photos without stamp","Compliant")) | P2: Possible AI-edited photo (2)
A3: SL02480 | B3: B Venkataiah | C3: KAE | D3: South | E3: Hyderabad | F3: K.Purushotham | G3: =COUNTIF('Claim Review'!$B$2:$B$202,A3) | H3: =COUNTIF('Photo Review'!$B$2:$B$403,A3) | I3: =COUNTIFS('Photo Review'!$B$2:$B$403,A3,'Photo Review'!$X$2:$X$403,"Yes") | J3: =H3-I3 | K3: =COUNTIFS('Claim Review'!$B$2:$B$202,A3,'Claim Review'!$M$2:$M$202,"NON-COMPLIANT") | L3: =SUMIFS('Claim Review'!$J$2:$J$202,'Claim Review'!$B$2:$B$202,A3,'Claim Review'!$M$2:$M$202,"NON-COMPLIANT") | M3: =SUMIFS('Claim Review'!$J$2:$J$202,'Claim Review'!$B$2:$B$202,A3) | N3: =COUNTIFS('Photo Review'!$B$2:$B$403,A3,'Photo Review'!$T$2:$T$403,"High") | O3: =IF(I3=0,"No stamp on any photo",IF(J3>0,"Some photos without stamp","Compliant")) | P3: Reused photo (2)
A4: SL03702 | B4: MASTR ANSARI VASIMAEHNAD | C4: SR | D4: GTR06 B | E4: VADODARA | F4: DEEPAK TUKARAM DESHMUKH | G4: =COUNTIF('Claim Review'!$B$2:$B$202,A4) | H4: =COUNTIF('Photo Review'!$B$2:$B$403,A4) | I4: =COUNTIFS('Photo Review'!$B$2:$B$403,A4,'Photo Review'!$X$2:$X$403,"Yes") | J4: =H4-I4 | K4: =COUNTIFS('Claim Review'!$B$2:$B$202,A4,'Claim Review'!$M$2:$M$202,"NON-COMPLIANT") | L4: =SUMIFS('Claim Review'!$J$2:$J$202,'Claim Review'!$B$2:$B$202,A4,'Claim Review'!$M$2:$M$202,"NON-COMPLIANT") | M4: =SUMIFS('Claim Review'!$J$2:$J$202,'Claim Review'!$B$2:$B$202,A4) | N4: =COUNTIFS('Photo Review'!$B$2:$B$403,A4,'Photo Review'!$T$2:$T$403,"High") | O4: =IF(I4=0,"No stamp on any photo",IF(J4>0,"Some photos without stamp","Compliant")) | P4: Reused photo (4)
A5: SL04125 | B5: ARVIND KUMAR DUBEY | C5: ASE | D5: GTR02 | E5: NORTH AND EAST DELHI | F5: RAHUL GAUTAM | G5: =COUNTIF('Claim Review'!$B$2:$B$202,A5) | H5: =COUNTIF('Photo Review'!$B$2:$B$403,A5) | I5: =COUNTIFS('Photo Review'!$B$2:$B$403,A5,'Photo Review'!$X$2:$X$403,"Yes") | J5: =H5-I5 | K5: =COUNTIFS('Claim Review'!$B$2:$B$202,A5,'Claim Review'!$M$2:$M$202,"NON-COMPLIANT") | L5: =SUMIFS('Claim Review'!$J$2:$J$202,'Claim Review'!$B$2:$B$202,A5,'Claim Review'!$M$2:$M$202,"NON-COMPLIANT") | M5: =SUMIFS('Claim Review'!$J$2:$J$202,'Claim Review'!$B$2:$B$202,A5) | N5: =COUNTIFS('Photo Review'!$B$2:$B$403,A5,'Photo Review'!$T$2:$T$403,"High") | O5: =IF(I5=0,"No stamp on any photo",IF(J5>0,"Some photos without stamp","Compliant")) | P5: Reused photo (4)
A6: SL04134 | B6: Babu Madhanagiriyappa | C6: SO | D6: GTR08 | E6: Bangalore | F6: P VIJAY KUMAR | G6: =COUNTIF('Claim Review'!$B$2:$B$202,A6) | H6: =COUNTIF('Photo Review'!$B$2:$B$403,A6) | I6: =COUNTIFS('Photo Review'!$B$2:$B$403,A6,'Photo Review'!$X$2:$X$403,"Yes") | J6: =H6-I6 | K6: =COUNTIFS('Claim Review'!$B$2:$B$202,A6,'Claim Review'!$M$2:$M$202,"NON-COMPLIANT") | L6: =SUMIFS('Claim Review'!$J$2:$J$202,'Claim Review'!$B$2:$B$202,A6,'Claim Review'!$M$2:$M$202,"NON-COMPLIANT") | M6: =SUMIFS('Claim Review'!$J$2:$J$202,'Claim Review'!$B$2:$B$202,A6) | N6: =COUNTIFS('Photo Review'!$B$2:$B$403,A6,'Photo Review'!$T$2:$T$403,"High") | O6: =IF(I6=0,"No stamp on any photo",IF(J6>0,"Some photos without stamp","Compliant")) | P6: Reused photo (2)
A7: SL04205 | B7: VINOD KUMAR | C7: SR | D7: North | E7: Delhi | F7: Gouri Shankar | G7: =COUNTIF('Claim Review'!$B$2:$B$202,A7) | H7: =COUNTIF('Photo Review'!$B$2:$B$403,A7) | I7: =COUNTIFS('Photo Review'!$B$2:$B$403,A7,'Photo Review'!$X$2:$X$403,"Yes") | J7: =H7-I7 | K7: =COUNTIFS('Claim Review'!$B$2:$B$202,A7,'Claim Review'!$M$2:$M$202,"NON-COMPLIANT") | L7: =SUMIFS('Claim Review'!$J$2:$J$202,'Claim Review'!$B$2:$B$202,A7,'Claim Review'!$M$2:$M$202,"NON-COMPLIANT") | M7: =SUMIFS('Claim Review'!$J$2:$J$202,'Claim Review'!$B$2:$B$202,A7) | N7: =COUNTIFS('Photo Review'!$B$2:$B$403,A7,'Photo Review'!$T$2:$T$403,"High") | O7: =IF(I7=0,"No stamp on any photo",IF(J7>0,"Some photos without stamp","Compliant")) | P7: Reused photo (10)
A8: SL04356 | B8: HARIOM DUBEY | C8: SO | D8: GTR02 | E8: New Delhi | F8: RAHUL GAUTAM | G8: =COUNTIF('Claim Review'!$B$2:$B$202,A8) | H8: =COUNTIF('Photo Review'!$B$2:$B$403,A8) | I8: =COUNTIFS('Photo Review'!$B$2:$B$403,A8,'Photo Review'!$X$2:$X$403,"Yes") | J8: =H8-I8 | K8: =COUNTIFS('Claim Review'!$B$2:$B$202,A8,'Claim Review'!$M$2:$M$202,"NON-COMPLIANT") | L8: =SUMIFS('Claim Review'!$J$2:$J$202,'Claim Review'!$B$2:$B$202,A8,'Claim Review'!$M$2:$M$202,"NON-COMPLIANT") | M8: =SUMIFS('Claim Review'!$J$2:$J$202,'Claim Review'!$B$2:$B$202,A8) | N8: =COUNTIFS('Photo Review'!$B$2:$B$403,A8,'Photo Review'!$T$2:$T$403,"High") | O8: =IF(I8=0,"No stamp on any photo",IF(J8>0,"Some photos without stamp","Compliant")) | P8: Reused photo (4)
A9: SL04426 | B9: P VIJAY KUMAR | C9: TSM | D9: GTR08 | E9: Bangalore | F9: REVANASIDDAPPA | G9: =COUNTIF('Claim Review'!$B$2:$B$202,A9) | H9: =COUNTIF('Photo Review'!$B$2:$B$403,A9) | I9: =COUNTIFS('Photo Review'!$B$2:$B$403,A9,'Photo Review'!$X$2:$X$403,"Yes") | J9: =H9-I9 | K9: =COUNTIFS('Claim Review'!$B$2:$B$202,A9,'Claim Review'!$M$2:$M$202,"NON-COMPLIANT") | L9: =SUMIFS('Claim Review'!$J$2:$J$202,'Claim Review'!$B$2:$B$202,A9,'Claim Review'!$M$2:$M$202,"NON-COMPLIANT") | M9: =SUMIFS('Claim Review'!$J$2:$J$202,'Claim Review'!$B$2:$B$202,A9) | N9: =COUNTIFS('Photo Review'!$B$2:$B$403,A9,'Photo Review'!$T$2:$T$403,"High") | O9: =IF(I9=0,"No stamp on any photo",IF(J9>0,"Some photos without stamp","Compliant")) | P9: Odometer END below START (1)
A10: SL04429 | B10: KISHAN KUMAR | C10: SO | D10: GTR02 | E10: West Delhi | F10: RAHUL GAUTAM | G10: =COUNTIF('Claim Review'!$B$2:$B$202,A10) | H10: =COUNTIF('Photo Review'!$B$2:$B$403,A10) | I10: =COUNTIFS('Photo Review'!$B$2:$B$403,A10,'Photo Review'!$X$2:$X$403,"Yes") | J10: =H10-I10 | K10: =COUNTIFS('Claim Review'!$B$2:$B$202,A10,'Claim Review'!$M$2:$M$202,"NON-COMPLIANT") | L10: =SUMIFS('Claim Review'!$J$2:$J$202,'Claim Review'!$B$2:$B$202,A10,'Claim Review'!$M$2:$M$202,"NON-COMPLIANT") | M10: =SUMIFS('Claim Review'!$J$2:$J$202,'Claim Review'!$B$2:$B$202,A10) | N10: =COUNTIFS('Photo Review'!$B$2:$B$403,A10,'Photo Review'!$T$2:$T$403,"High") | O10: =IF(I10=0,"No stamp on any photo",IF(J10>0,"Some photos without stamp","Compliant")) | P10: Reused photo (2)
A11: SL04461 | B11: KAFIL AHMAD KHAN | C11: SO | D11: GTR03 B | E11: Shahjahanpur | F11: SAURABH JAISWAL | G11: =COUNTIF('Claim Review'!$B$2:$B$202,A11) | H11: =COUNTIF('Photo Review'!$B$2:$B$403,A11) | I11: =COUNTIFS('Photo Review'!$B$2:$B$403,A11,'Photo Review'!$X$2:$X$403,"Yes") | J11: =H11-I11 | K11: =COUNTIFS('Claim Review'!$B$2:$B$202,A11,'Claim Review'!$M$2:$M$202,"NON-COMPLIANT") | L11: =SUMIFS('Claim Review'!$J$2:$J$202,'Claim Review'!$B$2:$B$202,A11,'Claim Review'!$M$2:$M$202,"NON-COMPLIANT") | M11: =SUMIFS('Claim Review'!$J$2:$J$202,'Claim Review'!$B$2:$B$202,A11) | N11: =COUNTIFS('Photo Review'!$B$2:$B$403,A11,'Photo Review'!$T$2:$T$403,"High") | O11: =IF(I11=0,"No stamp on any photo",IF(J11>0,"Some photos without stamp","Compliant")) | P11: Reused photo (4)
A12: SL04547 | B12: BALRAM VERMA | C12: SO | D12: GTR02 | E12: East Delhi | F12: RAHUL GAUTAM | G12: =COUNTIF('Claim Review'!$B$2:$B$202,A12) | H12: =COUNTIF('Photo Review'!$B$2:$B$403,A12) | I12: =COUNTIFS('Photo Review'!$B$2:$B$403,A12,'Photo Review'!$X$2:$X$403,"Yes") | J12: =H12-I12 | K12: =COUNTIFS('Claim Review'!$B$2:$B$202,A12,'Claim Review'!$M$2:$M$202,"NON-COMPLIANT") | L12: =SUMIFS('Claim Review'!$J$2:$J$202,'Claim Review'!$B$2:$B$202,A12,'Claim Review'!$M$2:$M$202,"NON-COMPLIANT") | M12: =SUMIFS('Claim Review'!$J$2:$J$202,'Claim Review'!$B$2:$B$202,A12) | N12: =COUNTIFS('Photo Review'!$B$2:$B$403,A12,'Photo Review'!$T$2:$T$403,"High") | O12: =IF(I12=0,"No stamp on any photo",IF(J12>0,"Some photos without stamp","Compliant")) | P12: Reused photo (6)
A13: SL04576 | B13: G SUGIRTHA RAJA | C13: SO | D13: GTR09 | E13: Salem | F13: Saravanan N | G13: =COUNTIF('Claim Review'!$B$2:$B$202,A13) | H13: =COUNTIF('Photo Review'!$B$2:$B$403,A13) | I13: =COUNTIFS('Photo Review'!$B$2:$B$403,A13,'Photo Review'!$X$2:$X$403,"Yes") | J13: =H13-I13 | K13: =COUNTIFS('Claim Review'!$B$2:$B$202,A13,'Claim Review'!$M$2:$M$202,"NON-COMPLIANT") | L13: =SUMIFS('Claim Review'!$J$2:$J$202,'Claim Review'!$B$2:$B$202,A13,'Claim Review'!$M$2:$M$202,"NON-COMPLIANT") | M13: =SUMIFS('Claim Review'!$J$2:$J$202,'Claim Review'!$B$2:$B$202,A13) | N13: =COUNTIFS('Photo Review'!$B$2:$B$403,A13,'Photo Review'!$T$2:$T$403,"High") | O13: =IF(I13=0,"No stamp on any photo",IF(J13>0,"Some photos without stamp","Compliant")) | P13: Reused photo (2)
A14: SL04446 | B14: GANDROTHULA SUBBA RAO | C14: SR | D14: GTR07 | E14: RAJMUNDRY | F14: Yellapu Nageswara Rao | G14: =COUNTIF('Claim Review'!$B$2:$B$202,A14) | H14: =COUNTIF('Photo Review'!$B$2:$B$403,A14) | I14: =COUNTIFS('Photo Review'!$B$2:$B$403,A14,'Photo Review'!$X$2:$X$403,"Yes") | J14: =H14-I14 | K14: =COUNTIFS('Claim Review'!$B$2:$B$202,A14,'Claim Review'!$M$2:$M$202,"NON-COMPLIANT") | L14: =SUMIFS('Claim Review'!$J$2:$J$202,'Claim Review'!$B$2:$B$202,A14,'Claim Review'!$M$2:$M$202,"NON-COMPLIANT") | M14: =SUMIFS('Claim Review'!$J$2:$J$202,'Claim Review'!$B$2:$B$202,A14) | N14: =COUNTIFS('Photo Review'!$B$2:$B$403,A14,'Photo Review'!$T$2:$T$403,"High") | O14: =IF(I14=0,"No stamp on any photo",IF(J14>0,"Some photos without stamp","Compliant")) | P14: Screenshot instead of photo (2)
A15: SL01707 | B15: PANKAJ KUMAR PANDEY | C15: SO | D15: GTR03 A | E15: FAIZABAD | F15: PRADEEP KUMAR | G15: =COUNTIF('Claim Review'!$B$2:$B$202,A15) | H15: =COUNTIF('Photo Review'!$B$2:$B$403,A15) | I15: =COUNTIFS('Photo Review'!$B$2:$B$403,A15,'Photo Review'!$X$2:$X$403,"Yes") | J15: =H15-I15 | K15: =COUNTIFS('Claim Review'!$B$2:$B$202,A15,'Claim Review'!$M$2:$M$202,"NON-COMPLIANT") | L15: =SUMIFS('Claim Review'!$J$2:$J$202,'Claim Review'!$B$2:$B$202,A15,'Claim Review'!$M$2:$M$202,"NON-COMPLIANT") | M15: =SUMIFS('Claim Review'!$J$2:$J$202,'Claim Review'!$B$2:$B$202,A15) | N15: =COUNTIFS('Photo Review'!$B$2:$B$403,A15,'Photo Review'!$T$2:$T$403,"High") | O15: =IF(I15=0,"No stamp on any photo",IF(J15>0,"Some photos without stamp","Compliant"))
A16: SL02068 | B16: ZEVER FARNONDES | C16: SO | D16: GTR08 | E16: PANJIM | F16: MANOHAR KUMAR JHA | G16: =COUNTIF('Claim Review'!$B$2:$B$202,A16) | H16: =COUNTIF('Photo Review'!$B$2:$B$403,A16) | I16: =COUNTIFS('Photo Review'!$B$2:$B$403,A16,'Photo Review'!$X$2:$X$403,"Yes") | J16: =H16-I16 | K16: =COUNTIFS('Claim Review'!$B$2:$B$202,A16,'Claim Review'!$M$2:$M$202,"NON-COMPLIANT") | L16: =SUMIFS('Claim Review'!$J$2:$J$202,'Claim Review'!$B$2:$B$202,A16,'Claim Review'!$M$2:$M$202,"NON-COMPLIANT") | M16: =SUMIFS('Claim Review'!$J$2:$J$202,'Claim Review'!$B$2:$B$202,A16) | N16: =COUNTIFS('Photo Review'!$B$2:$B$403,A16,'Photo Review'!$T$2:$T$403,"High") | O16: =IF(I16=0,"No stamp on any photo",IF(J16>0,"Some photos without stamp","Compliant"))
A17: SL02611 | B17: Mahesh Kumar Gujjari | C17: SO | D17: South | E17: HYDERABAD | F17: K.Purushotham | G17: =COUNTIF('Claim Review'!$B$2:$B$202,A17) | H17: =COUNTIF('Photo Review'!$B$2:$B$403,A17) | I17: =COUNTIFS('Photo Review'!$B$2:$B$403,A17,'Photo Review'!$X$2:$X$403,"Yes") | J17: =H17-I17 | K17: =COUNTIFS('Claim Review'!$B$2:$B$202,A17,'Claim Review'!$M$2:$M$202,"NON-COMPLIANT") | L17: =SUMIFS('Claim Review'!$J$2:$J$202,'Claim Review'!$B$2:$B$202,A17,'Claim Review'!$M$2:$M$202,"NON-COMPLIANT") | M17: =SUMIFS('Claim Review'!$J$2:$J$202,'Claim Review'!$B$2:$B$202,A17) | N17: =COUNTIFS('Photo Review'!$B$2:$B$403,A17,'Photo Review'!$T$2:$T$403,"High") | O17: =IF(I17=0,"No stamp on any photo",IF(J17>0,"Some photos without stamp","Compliant"))
A18: SL02671 | B18: IBRAR ALAM | C18: SR | D18: GTR02 | E18: EAST DELHI | F18: RAHUL GAUTAM | G18: =COUNTIF('Claim Review'!$B$2:$B$202,A18) | H18: =COUNTIF('Photo Review'!$B$2:$B$403,A18) | I18: =COUNTIFS('Photo Review'!$B$2:$B$403,A18,'Photo Review'!$X$2:$X$403,"Yes") | J18: =H18-I18 | K18: =COUNTIFS('Claim Review'!$B$2:$B$202,A18,'Claim Review'!$M$2:$M$202,"NON-COMPLIANT") | L18: =SUMIFS('Claim Review'!$J$2:$J$202,'Claim Review'!$B$2:$B$202,A18,'Claim Review'!$M$2:$M$202,"NON-COMPLIANT") | M18: =SUMIFS('Claim Review'!$J$2:$J$202,'Claim Review'!$B$2:$B$202,A18) | N18: =COUNTIFS('Photo Review'!$B$2:$B$403,A18,'Photo Review'!$T$2:$T$403,"High") | O18: =IF(I18=0,"No stamp on any photo",IF(J18>0,"Some photos without stamp","Compliant"))
A19: SL02930 | B19: A. SURESH GOUD | C19: SR | D19: GTR07 | E19: Jadcherla | F19: B BHASKAR | G19: =COUNTIF('Claim Review'!$B$2:$B$202,A19) | H19: =COUNTIF('Photo Review'!$B$2:$B$403,A19) | I19: =COUNTIFS('Photo Review'!$B$2:$B$403,A19,'Photo Review'!$X$2:$X$403,"Yes") | J19: =H19-I19 | K19: =COUNTIFS('Claim Review'!$B$2:$B$202,A19,'Claim Review'!$M$2:$M$202,"NON-COMPLIANT") | L19: =SUMIFS('Claim Review'!$J$2:$J$202,'Claim Review'!$B$2:$B$202,A19,'Claim Review'!$M$2:$M$202,"NON-COMPLIANT") | M19: =SUMIFS('Claim Review'!$J$2:$J$202,'Claim Review'!$B$2:$B$202,A19) | N19: =COUNTIFS('Photo Review'!$B$2:$B$403,A19,'Photo Review'!$T$2:$T$403,"High") | O19: =IF(I19=0,"No stamp on any photo",IF(J19>0,"Some photos without stamp","Compliant"))
A20: SL03708 | B20: ARUMANI M | C20: SO | D20: GTR09 | E20: CHENNAI | F20: Saravanan N | G20: =COUNTIF('Claim Review'!$B$2:$B$202,A20) | H20: =COUNTIF('Photo Review'!$B$2:$B$403,A20) | I20: =COUNTIFS('Photo Review'!$B$2:$B$403,A20,'Photo Review'!$X$2:$X$403,"Yes") | J20: =H20-I20 | K20: =COUNTIFS('Claim Review'!$B$2:$B$202,A20,'Claim Review'!$M$2:$M$202,"NON-COMPLIANT") | L20: =SUMIFS('Claim Review'!$J$2:$J$202,'Claim Review'!$B$2:$B$202,A20,'Claim Review'!$M$2:$M$202,"NON-COMPLIANT") | M20: =SUMIFS('Claim Review'!$J$2:$J$202,'Claim Review'!$B$2:$B$202,A20) | N20: =COUNTIFS('Photo Review'!$B$2:$B$403,A20,'Photo Review'!$T$2:$T$403,"High") | O20: =IF(I20=0,"No stamp on any photo",IF(J20>0,"Some photos without stamp","Compliant"))
A21: SL03991 | B21: BHATTARU SETTI RAMESH | C21: SO | D21: GTR07 | E21: HYDERABAD | F21: SHIVAKANTH SAPA | G21: =COUNTIF('Claim Review'!$B$2:$B$202,A21) | H21: =COUNTIF('Photo Review'!$B$2:$B$403,A21) | I21: =COUNTIFS('Photo Review'!$B$2:$B$403,A21,'Photo Review'!$X$2:$X$403,"Yes") | J21: =H21-I21 | K21: =COUNTIFS('Claim Review'!$B$2:$B$202,A21,'Claim Review'!$M$2:$M$202,"NON-COMPLIANT") | L21: =SUMIFS('Claim Review'!$J$2:$J$202,'Claim Review'!$B$2:$B$202,A21,'Claim Review'!$M$2:$M$202,"NON-COMPLIANT") | M21: =SUMIFS('Claim Review'!$J$2:$J$202,'Claim Review'!$B$2:$B$202,A21) | N21: =COUNTIFS('Photo Review'!$B$2:$B$403,A21,'Photo Review'!$T$2:$T$403,"High") | O21: =IF(I21=0,"No stamp on any photo",IF(J21>0,"Some photos without stamp","Compliant"))
A22: SL04109 | B22: Medudula Santhosh Kumar | C22: SO | D22: GTR07 | E22: Hyderabad | F22: SHIVAKANTH SAPA | G22: =COUNTIF('Claim Review'!$B$2:$B$202,A22) | H22: =COUNTIF('Photo Review'!$B$2:$B$403,A22) | I22: =COUNTIFS('Photo Review'!$B$2:$B$403,A22,'Photo Review'!$X$2:$X$403,"Yes") | J22: =H22-I22 | K22: =COUNTIFS('Claim Review'!$B$2:$B$202,A22,'Claim Review'!$M$2:$M$202,"NON-COMPLIANT") | L22: =SUMIFS('Claim Review'!$J$2:$J$202,'Claim Review'!$B$2:$B$202,A22,'Claim Review'!$M$2:$M$202,"NON-COMPLIANT") | M22: =SUMIFS('Claim Review'!$J$2:$J$202,'Claim Review'!$B$2:$B$202,A22) | N22: =COUNTIFS('Photo Review'!$B$2:$B$403,A22,'Photo Review'!$T$2:$T$403,"High") | O22: =IF(I22=0,"No stamp on any photo",IF(J22>0,"Some photos without stamp","Compliant"))
A23: SL04130 | B23: RAJESH KUMAR SHARMA | C23: SO | D23: GTR01 | E23: Bilaspur | F23: MOHINDER SHARMA | G23: =COUNTIF('Claim Review'!$B$2:$B$202,A23) | H23: =COUNTIF('Photo Review'!$B$2:$B$403,A23) | I23: =COUNTIFS('Photo Review'!$B$2:$B$403,A23,'Photo Review'!$X$2:$X$403,"Yes") | J23: =H23-I23 | K23: =COUNTIFS('Claim Review'!$B$2:$B$202,A23,'Claim Review'!$M$2:$M$202,"NON-COMPLIANT") | L23: =SUMIFS('Claim Review'!$J$2:$J$202,'Claim Review'!$B$2:$B$202,A23,'Claim Review'!$M$2:$M$202,"NON-COMPLIANT") | M23: =SUMIFS('Claim Review'!$J$2:$J$202,'Claim Review'!$B$2:$B$202,A23) | N23: =COUNTIFS('Photo Review'!$B$2:$B$403,A23,'Photo Review'!$T$2:$T$403,"High") | O23: =IF(I23=0,"No stamp on any photo",IF(J23>0,"Some photos without stamp","Compliant"))
A24: SL04150 | B24: SUBHASH GANESH MANDVE | C24: SO | D24: West | E24: NAGPUR | F24: POKHRAJ KUMAR SAHU | G24: =COUNTIF('Claim Review'!$B$2:$B$202,A24) | H24: =COUNTIF('Photo Review'!$B$2:$B$403,A24) | I24: =COUNTIFS('Photo Review'!$B$2:$B$403,A24,'Photo Review'!$X$2:$X$403,"Yes") | J24: =H24-I24 | K24: =COUNTIFS('Claim Review'!$B$2:$B$202,A24,'Claim Review'!$M$2:$M$202,"NON-COMPLIANT") | L24: =SUMIFS('Claim Review'!$J$2:$J$202,'Claim Review'!$B$2:$B$202,A24,'Claim Review'!$M$2:$M$202,"NON-COMPLIANT") | M24: =SUMIFS('Claim Review'!$J$2:$J$202,'Claim Review'!$B$2:$B$202,A24) | N24: =COUNTIFS('Photo Review'!$B$2:$B$403,A24,'Photo Review'!$T$2:$T$403,"High") | O24: =IF(I24=0,"No stamp on any photo",IF(J24>0,"Some photos without stamp","Compliant"))
A25: SL04184 | B25: PANGAJAM U | C25: SR | D25: South | E25: Coimbatore | F25: SURENDRAN R | G25: =COUNTIF('Claim Review'!$B$2:$B$202,A25) | H25: =COUNTIF('Photo Review'!$B$2:$B$403,A25) | I25: =COUNTIFS('Photo Review'!$B$2:$B$403,A25,'Photo Review'!$X$2:$X$403,"Yes") | J25: =H25-I25 | K25: =COUNTIFS('Claim Review'!$B$2:$B$202,A25,'Claim Review'!$M$2:$M$202,"NON-COMPLIANT") | L25: =SUMIFS('Claim Review'!$J$2:$J$202,'Claim Review'!$B$2:$B$202,A25,'Claim Review'!$M$2:$M$202,"NON-COMPLIANT") | M25: =SUMIFS('Claim Review'!$J$2:$J$202,'Claim Review'!$B$2:$B$202,A25) | N25: =COUNTIFS('Photo Review'!$B$2:$B$403,A25,'Photo Review'!$T$2:$T$403,"High") | O25: =IF(I25=0,"No stamp on any photo",IF(J25>0,"Some photos without stamp","Compliant"))
A26: SL04206 | B26: BHARATKUMAR BHOGILAL SUTHAR | C26: ASE | D26: GTR06 B | E26: Ahmedabad | F26: DEEPAK TUKARAM DESHMUKH | G26: =COUNTIF('Claim Review'!$B$2:$B$202,A26) | H26: =COUNTIF('Photo Review'!$B$2:$B$403,A26) | I26: =COUNTIFS('Photo Review'!$B$2:$B$403,A26,'Photo Review'!$X$2:$X$403,"Yes") | J26: =H26-I26 | K26: =COUNTIFS('Claim Review'!$B$2:$B$202,A26,'Claim Review'!$M$2:$M$202,"NON-COMPLIANT") | L26: =SUMIFS('Claim Review'!$J$2:$J$202,'Claim Review'!$B$2:$B$202,A26,'Claim Review'!$M$2:$M$202,"NON-COMPLIANT") | M26: =SUMIFS('Claim Review'!$J$2:$J$202,'Claim Review'!$B$2:$B$202,A26) | N26: =COUNTIFS('Photo Review'!$B$2:$B$403,A26,'Photo Review'!$T$2:$T$403,"High") | O26: =IF(I26=0,"No stamp on any photo",IF(J26>0,"Some photos without stamp","Compliant"))
... A44: SL04578 | B44: MUKESH CHANDERA JOSHI | C44: SO | D44: GTR03 B | E44: Srinagar | F44: SUNEEL KUMAR | G44: =COUNTIF('Claim Review'!$B$2:$B$202,A44) | H44: =COUNTIF('Photo Review'!$B$2:$B$403,A44) | I44: =COUNTIFS('Photo Review'!$B$2:$B$403,A44,'Photo Review'!$X$2:$X$403,"Yes") | J44: =H44-I44 | K44: =COUNTIFS('Claim Review'!$B$2:$B$202,A44,'Claim Review'!$M$2:$M$202,"NON-COMPLIANT") | L44: =SUMIFS('Claim Review'!$J$2:$J$202,'Claim Review'!$B$2:$B$202,A44,'Claim Review'!$M$2:$M$202,"NON-COMPLIANT") | M44: =SUMIFS('Claim Review'!$J$2:$J$202,'Claim Review'!$B$2:$B$202,A44) | N44: =COUNTIFS('Photo Review'!$B$2:$B$403,A44,'Photo Review'!$T$2:$T$403,"High") | O44: =IF(I44=0,"No stamp on any photo",IF(J44>0,"Some photos without stamp","Compliant"))
A45: SL04617 | B45: ASIF SAMEJA | C45: SR | D45: GTR02 | E45: BIKANER | G45: =COUNTIF('Claim Review'!$B$2:$B$202,A45) | H45: =COUNTIF('Photo Review'!$B$2:$B$403,A45) | I45: =COUNTIFS('Photo Review'!$B$2:$B$403,A45,'Photo Review'!$X$2:$X$403,"Yes") | J45: =H45-I45 | K45: =COUNTIFS('Claim Review'!$B$2:$B$202,A45,'Claim Review'!$M$2:$M$202,"NON-COMPLIANT") | L45: =SUMIFS('Claim Review'!$J$2:$J$202,'Claim Review'!$B$2:$B$202,A45,'Claim Review'!$M$2:$M$202,"NON-COMPLIANT") | M45: =SUMIFS('Claim Review'!$J$2:$J$202,'Claim Review'!$B$2:$B$202,A45) | N45: =COUNTIFS('Photo Review'!$B$2:$B$403,A45,'Photo Review'!$T$2:$T$403,"High") | O45: =IF(I45=0,"No stamp on any photo",IF(J45>0,"Some photos without stamp","Compliant"))
A46: SL00170 | B46: MUJAHID . | C46: SSO | D46: GTR02 | E46: GURUGRAM | F46: PUNEET WADHWA | G46: =COUNTIF('Claim Review'!$B$2:$B$202,A46) | H46: =COUNTIF('Photo Review'!$B$2:$B$403,A46) | I46: =COUNTIFS('Photo Review'!$B$2:$B$403,A46,'Photo Review'!$X$2:$X$403,"Yes") | J46: =H46-I46 | K46: =COUNTIFS('Claim Review'!$B$2:$B$202,A46,'Claim Review'!$M$2:$M$202,"NON-COMPLIANT") | L46: =SUMIFS('Claim Review'!$J$2:$J$202,'Claim Review'!$B$2:$B$202,A46,'Claim Review'!$M$2:$M$202,"NON-COMPLIANT") | M46: =SUMIFS('Claim Review'!$J$2:$J$202,'Claim Review'!$B$2:$B$202,A46) | N46: =COUNTIFS('Photo Review'!$B$2:$B$403,A46,'Photo Review'!$T$2:$T$403,"High") | O46: =IF(I46=0,"No stamp on any photo",IF(J46>0,"Some photos without stamp","Compliant")) | P46: Reused photo (4) | Photo dated after the claim date (2) | Photo dated after claim was submitted (2) | END photo taken before START (2)
A47: SL02286 | B47: AMIT KUMAR SINGH | C47: ASE | D47: GTR03 A | E47: Lucknow | F47: SAURABH JAISWAL | G47: =COUNTIF('Claim Review'!$B$2:$B$202,A47) | H47: =COUNTIF('Photo Review'!$B$2:$B$403,A47) | I47: =COUNTIFS('Photo Review'!$B$2:$B$403,A47,'Photo Review'!$X$2:$X$403,"Yes") | J47: =H47-I47 | K47: =COUNTIFS('Claim Review'!$B$2:$B$202,A47,'Claim Review'!$M$2:$M$202,"NON-COMPLIANT") | L47: =SUMIFS('Claim Review'!$J$2:$J$202,'Claim Review'!$B$2:$B$202,A47,'Claim Review'!$M$2:$M$202,"NON-COMPLIANT") | M47: =SUMIFS('Claim Review'!$J$2:$J$202,'Claim Review'!$B$2:$B$202,A47) | N47: =COUNTIFS('Photo Review'!$B$2:$B$403,A47,'Photo Review'!$T$2:$T$403,"High") | O47: =IF(I47=0,"No stamp on any photo",IF(J47>0,"Some photos without stamp","Compliant")) | P47: Reused photo (4) | Stamp date does not match claim (2) | Photo dated after the claim date (1)
A48: SL02826 | B48: KIRAN KUMAR NAYAK | C48: SR | D48: GTR08 | E48: BANGALORE | F48: GANGADHARAM K | G48: =COUNTIF('Claim Review'!$B$2:$B$202,A48) | H48: =COUNTIF('Photo Review'!$B$2:$B$403,A48) | I48: =COUNTIFS('Photo Review'!$B$2:$B$403,A48,'Photo Review'!$X$2:$X$403,"Yes") | J48: =H48-I48 | K48: =COUNTIFS('Claim Review'!$B$2:$B$202,A48,'Claim Review'!$M$2:$M$202,"NON-COMPLIANT") | L48: =SUMIFS('Claim Review'!$J$2:$J$202,'Claim Review'!$B$2:$B$202,A48,'Claim Review'!$M$2:$M$202,"NON-COMPLIANT") | M48: =SUMIFS('Claim Review'!$J$2:$J$202,'Claim Review'!$B$2:$B$202,A48) | N48: =COUNTIFS('Photo Review'!$B$2:$B$403,A48,'Photo Review'!$T$2:$T$403,"High") | O48: =IF(I48=0,"No stamp on any photo",IF(J48>0,"Some photos without stamp","Compliant")) | P48: Photo dated after the claim date (4) | Reused photo (2)
A49: SL03855 | B49: PRAVEEN SHARMA | C49: SR | D49: GTR02 | E49: JAIPUR | F49: VINAY SHARMA | G49: =COUNTIF('Claim Review'!$B$2:$B$202,A49) | H49: =COUNTIF('Photo Review'!$B$2:$B$403,A49) | I49: =COUNTIFS('Photo Review'!$B$2:$B$403,A49,'Photo Review'!$X$2:$X$403,"Yes") | J49: =H49-I49 | K49: =COUNTIFS('Claim Review'!$B$2:$B$202,A49,'Claim Review'!$M$2:$M$202,"NON-COMPLIANT") | L49: =SUMIFS('Claim Review'!$J$2:$J$202,'Claim Review'!$B$2:$B$202,A49,'Claim Review'!$M$2:$M$202,"NON-COMPLIANT") | M49: =SUMIFS('Claim Review'!$J$2:$J$202,'Claim Review'!$B$2:$B$202,A49) | N49: =COUNTIFS('Photo Review'!$B$2:$B$403,A49,'Photo Review'!$T$2:$T$403,"High") | O49: =IF(I49=0,"No stamp on any photo",IF(J49>0,"Some photos without stamp","Compliant")) | P49: Photo dated after the claim date (1) | Photo dated after claim was submitted (1)
A50: SL04004 | B50: PINKU KUMAR CHOUDHARI | C50: SR | D50: GTR04 B | E50: DEOGHAR | F50: AMIT KUMAR SINHA | G50: =COUNTIF('Claim Review'!$B$2:$B$202,A50) | H50: =COUNTIF('Photo Review'!$B$2:$B$403,A50) | I50: =COUNTIFS('Photo Review'!$B$2:$B$403,A50,'Photo Review'!$X$2:$X$403,"Yes") | J50: =H50-I50 | K50: =COUNTIFS('Claim Review'!$B$2:$B$202,A50,'Claim Review'!$M$2:$M$202,"NON-COMPLIANT") | L50: =SUMIFS('Claim Review'!$J$2:$J$202,'Claim Review'!$B$2:$B$202,A50,'Claim Review'!$M$2:$M$202,"NON-COMPLIANT") | M50: =SUMIFS('Claim Review'!$J$2:$J$202,'Claim Review'!$B$2:$B$202,A50) | N50: =COUNTIFS('Photo Review'!$B$2:$B$403,A50,'Photo Review'!$T$2:$T$403,"High") | O50: =IF(I50=0,"No stamp on any photo",IF(J50>0,"Some photos without stamp","Compliant")) | P50: END photo taken before START (1)
A51: SL04310 | B51: RAHUL GAUTAM | C51: ASM | D51: GTR02 | E51: New Delhi | F51: RAMESH SINGH | G51: =COUNTIF('Claim Review'!$B$2:$B$202,A51) | H51: =COUNTIF('Photo Review'!$B$2:$B$403,A51) | I51: =COUNTIFS('Photo Review'!$B$2:$B$403,A51,'Photo Review'!$X$2:$X$403,"Yes") | J51: =H51-I51 | K51: =COUNTIFS('Claim Review'!$B$2:$B$202,A51,'Claim Review'!$M$2:$M$202,"NON-COMPLIANT") | L51: =SUMIFS('Claim Review'!$J$2:$J$202,'Claim Review'!$B$2:$B$202,A51,'Claim Review'!$M$2:$M$202,"NON-COMPLIANT") | M51: =SUMIFS('Claim Review'!$J$2:$J$202,'Claim Review'!$B$2:$B$202,A51) | N51: =COUNTIFS('Photo Review'!$B$2:$B$403,A51,'Photo Review'!$T$2:$T$403,"High") | O51: =IF(I51=0,"No stamp on any photo",IF(J51>0,"Some photos without stamp","Compliant")) | P51: END photo taken before START (1)
A52: SL04428 | B52: ASHWANI KUMAR | C52: SO | D52: GTR02 | E52: Central Delhi | F52: RAHUL GAUTAM | G52: =COUNTIF('Claim Review'!$B$2:$B$202,A52) | H52: =COUNTIF('Photo Review'!$B$2:$B$403,A52) | I52: =COUNTIFS('Photo Review'!$B$2:$B$403,A52,'Photo Review'!$X$2:$X$403,"Yes") | J52: =H52-I52 | K52: =COUNTIFS('Claim Review'!$B$2:$B$202,A52,'Claim Review'!$M$2:$M$202,"NON-COMPLIANT") | L52: =SUMIFS('Claim Review'!$J$2:$J$202,'Claim Review'!$B$2:$B$202,A52,'Claim Review'!$M$2:$M$202,"NON-COMPLIANT") | M52: =SUMIFS('Claim Review'!$J$2:$J$202,'Claim Review'!$B$2:$B$202,A52) | N52: =COUNTIFS('Photo Review'!$B$2:$B$403,A52,'Photo Review'!$T$2:$T$403,"High") | O52: =IF(I52=0,"No stamp on any photo",IF(J52>0,"Some photos without stamp","Compliant")) | P52: Stamp date does not match claim (1)
A53: SL04464 | B53: RAVISHANKAR DHARAMRAJ MAURYA | C53: KAE | D53: North | E53: DELHI | F53: RISHI RAGHAV | G53: =COUNTIF('Claim Review'!$B$2:$B$202,A53) | H53: =COUNTIF('Photo Review'!$B$2:$B$403,A53) | I53: =COUNTIFS('Photo Review'!$B$2:$B$403,A53,'Photo Review'!$X$2:$X$403,"Yes") | J53: =H53-I53 | K53: =COUNTIFS('Claim Review'!$B$2:$B$202,A53,'Claim Review'!$M$2:$M$202,"NON-COMPLIANT") | L53: =SUMIFS('Claim Review'!$J$2:$J$202,'Claim Review'!$B$2:$B$202,A53,'Claim Review'!$M$2:$M$202,"NON-COMPLIANT") | M53: =SUMIFS('Claim Review'!$J$2:$J$202,'Claim Review'!$B$2:$B$202,A53) | N53: =COUNTIFS('Photo Review'!$B$2:$B$403,A53,'Photo Review'!$T$2:$T$403,"High") | O53: =IF(I53=0,"No stamp on any photo",IF(J53>0,"Some photos without stamp","Compliant")) | P53: Stamp date does not match claim (8) | Odometer reading goes backwards (1)
A54: SL04516 | B54: VINAY S | C54: SO | D54: GTR08 | E54: BIDADI | F54: P VIJAY KUMAR | G54: =COUNTIF('Claim Review'!$B$2:$B$202,A54) | H54: =COUNTIF('Photo Review'!$B$2:$B$403,A54) | I54: =COUNTIFS('Photo Review'!$B$2:$B$403,A54,'Photo Review'!$X$2:$X$403,"Yes") | J54: =H54-I54 | K54: =COUNTIFS('Claim Review'!$B$2:$B$202,A54,'Claim Review'!$M$2:$M$202,"NON-COMPLIANT") | L54: =SUMIFS('Claim Review'!$J$2:$J$202,'Claim Review'!$B$2:$B$202,A54,'Claim Review'!$M$2:$M$202,"NON-COMPLIANT") | M54: =SUMIFS('Claim Review'!$J$2:$J$202,'Claim Review'!$B$2:$B$202,A54) | N54: =COUNTIFS('Photo Review'!$B$2:$B$403,A54,'Photo Review'!$T$2:$T$403,"High") | O54: =IF(I54=0,"No stamp on any photo",IF(J54>0,"Some photos without stamp","Compliant")) | P54: Reused photo (2) | Stamp date does not match claim (1)
A55: SL04394 | B55: DHILIBAN M | C55: SO | D55: GTR09 | E55: Krishnagiri | F55: Saravanan N | G55: =COUNTIF('Claim Review'!$B$2:$B$202,A55) | H55: =COUNTIF('Photo Review'!$B$2:$B$403,A55) | I55: =COUNTIFS('Photo Review'!$B$2:$B$403,A55,'Photo Review'!$X$2:$X$403,"Yes") | J55: =H55-I55 | K55: =COUNTIFS('Claim Review'!$B$2:$B$202,A55,'Claim Review'!$M$2:$M$202,"NON-COMPLIANT") | L55: =SUMIFS('Claim Review'!$J$2:$J$202,'Claim Review'!$B$2:$B$202,A55,'Claim Review'!$M$2:$M$202,"NON-COMPLIANT") | M55: =SUMIFS('Claim Review'!$J$2:$J$202,'Claim Review'!$B$2:$B$202,A55) | N55: =COUNTIFS('Photo Review'!$B$2:$B$403,A55,'Photo Review'!$T$2:$T$403,"High") | O55: =IF(I55=0,"No stamp on any photo",IF(J55>0,"Some photos without stamp","Compliant")) | P55: Screenshot instead of photo (1)
A56: SL01966 | B56: SHASHIDHAR NAIR | C56: SO | D56: GTR08 | E56: BANGALORE | F56: GANGADHARAM K | G56: =COUNTIF('Claim Review'!$B$2:$B$202,A56) | H56: =COUNTIF('Photo Review'!$B$2:$B$403,A56) | I56: =COUNTIFS('Photo Review'!$B$2:$B$403,A56,'Photo Review'!$X$2:$X$403,"Yes") | J56: =H56-I56 | K56: =COUNTIFS('Claim Review'!$B$2:$B$202,A56,'Claim Review'!$M$2:$M$202,"NON-COMPLIANT") | L56: =SUMIFS('Claim Review'!$J$2:$J$202,'Claim Review'!$B$2:$B$202,A56,'Claim Review'!$M$2:$M$202,"NON-COMPLIANT") | M56: =SUMIFS('Claim Review'!$J$2:$J$202,'Claim Review'!$B$2:$B$202,A56) | N56: =COUNTIFS('Photo Review'!$B$2:$B$403,A56,'Photo Review'!$T$2:$T$403,"High") | O56: =IF(I56=0,"No stamp on any photo",IF(J56>0,"Some photos without stamp","Compliant"))
A57: SL03071 | B57: Bhavana Yadav | C57: SO | D57: West | E57: RAIPUR | F57: POKHRAJ KUMAR SAHU | G57: =COUNTIF('Claim Review'!$B$2:$B$202,A57) | H57: =COUNTIF('Photo Review'!$B$2:$B$403,A57) | I57: =COUNTIFS('Photo Review'!$B$2:$B$403,A57,'Photo Review'!$X$2:$X$403,"Yes") | J57: =H57-I57 | K57: =COUNTIFS('Claim Review'!$B$2:$B$202,A57,'Claim Review'!$M$2:$M$202,"NON-COMPLIANT") | L57: =SUMIFS('Claim Review'!$J$2:$J$202,'Claim Review'!$B$2:$B$202,A57,'Claim Review'!$M$2:$M$202,"NON-COMPLIANT") | M57: =SUMIFS('Claim Review'!$J$2:$J$202,'Claim Review'!$B$2:$B$202,A57) | N57: =COUNTIFS('Photo Review'!$B$2:$B$403,A57,'Photo Review'!$T$2:$T$403,"High") | O57: =IF(I57=0,"No stamp on any photo",IF(J57>0,"Some photos without stamp","Compliant"))
...

Sheet Claim Review
A1: Claim Key | B1: Employee_code | C1: User_Name | D1: Zone | E1: HQ | F1: L1 Approver | G1: Claim_Id | H1: Claim_Date | I1: Submit Date | J1: Claim_Amount (₹) | K1: START Result | L1: END Result | M1: Claim Result | N1: Odometer START (OCR) | O1: Odometer END (OCR) | P1: Odometer km (OCR) | Q1: Photos with Red Flags
A2: 2847 | B2: SL00147 | C2: Girish Kahar | D2: West | E2: VADODARA | F2: NAVEEN N ANCHAN | G2: 350983 | H2: 46312 | I2: 46312 | J2: 472 | K2: =IFERROR(INDEX('Photo Review'!$W$2:$W$403,MATCH($A2&"|START",'Photo Review'!$Z$2:$Z$403,0)),"Photo missing / not downloaded") | L2: =IFERROR(INDEX('Photo Review'!$W$2:$W$403,MATCH($A2&"|END",'Photo Review'!$Z$2:$Z$403,0)),"Photo missing / not downloaded") | M2: =IF(AND(K2="Timestamp + Location",L2="Timestamp + Location"),"Compliant","NON-COMPLIANT") | Q2: =COUNTIFS('Photo Review'!$J$2:$J$403,A2,'Photo Review'!$S$2:$S$403,"?*")
A3: 279 | B3: SL00170 | C3: MUJAHID . | D3: GTR02 | E3: GURUGRAM | F3: PUNEET WADHWA | G3: 348418 | H3: 46307 | I3: 46307 | J3: 516 | K3: =IFERROR(INDEX('Photo Review'!$W$2:$W$403,MATCH($A3&"|START",'Photo Review'!$Z$2:$Z$403,0)),"Photo missing / not downloaded") | L3: =IFERROR(INDEX('Photo Review'!$W$2:$W$403,MATCH($A3&"|END",'Photo Review'!$Z$2:$Z$403,0)),"Photo missing / not downloaded") | M3: =IF(AND(K3="Timestamp + Location",L3="Timestamp + Location"),"Compliant","NON-COMPLIANT") | N3: 7516 | O3: 7715 | P3: 199 | Q3: =COUNTIFS('Photo Review'!$J$2:$J$403,A3,'Photo Review'!$S$2:$S$403,"?*")
A4: 661 | B4: SL00170 | C4: MUJAHID . | D4: GTR02 | E4: GURUGRAM | F4: PUNEET WADHWA | G4: 348955 | H4: 46308 | I4: 46308 | J4: 400 | K4: =IFERROR(INDEX('Photo Review'!$W$2:$W$403,MATCH($A4&"|START",'Photo Review'!$Z$2:$Z$403,0)),"Photo missing / not downloaded") | L4: =IFERROR(INDEX('Photo Review'!$W$2:$W$403,MATCH($A4&"|END",'Photo Review'!$Z$2:$Z$403,0)),"Photo missing / not downloaded") | M4: =IF(AND(K4="Timestamp + Location",L4="Timestamp + Location"),"Compliant","NON-COMPLIANT") | N4: 7715 | O4: 7850 | P4: 135 | Q4: =COUNTIFS('Photo Review'!$J$2:$J$403,A4,'Photo Review'!$S$2:$S$403,"?*")
A5: 1027 | B5: SL00170 | C5: MUJAHID . | D5: GTR02 | E5: GURUGRAM | F5: PUNEET WADHWA | G5: 349374 | H5: 46309 | I5: 46309 | J5: 296 | K5: =IFERROR(INDEX('Photo Review'!$W$2:$W$403,MATCH($A5&"|START",'Photo Review'!$Z$2:$Z$403,0)),"Photo missing / not downloaded") | L5: =IFERROR(INDEX('Photo Review'!$W$2:$W$403,MATCH($A5&"|END",'Photo Review'!$Z$2:$Z$403,0)),"Photo missing / not downloaded") | M5: =IF(AND(K5="Timestamp + Location",L5="Timestamp + Location"),"Compliant","NON-COMPLIANT") | N5: 1022 | O5: 1032.9 | P5: 10.9 | Q5: =COUNTIFS('Photo Review'!$J$2:$J$403,A5,'Photo Review'!$S$2:$S$403,"?*")
A6: 1696 | B6: SL00170 | C6: MUJAHID . | D6: GTR02 | E6: GURUGRAM | F6: PUNEET WADHWA | G6: 350005 | H6: 46310 | I6: 46310 | J6: 448 | K6: =IFERROR(INDEX('Photo Review'!$W$2:$W$403,MATCH($A6&"|START",'Photo Review'!$Z$2:$Z$403,0)),"Photo missing / not downloaded") | L6: =IFERROR(INDEX('Photo Review'!$W$2:$W$403,MATCH($A6&"|END",'Photo Review'!$Z$2:$Z$403,0)),"Photo missing / not downloaded") | M6: =IF(AND(K6="Timestamp + Location",L6="Timestamp + Location"),"Compliant","NON-COMPLIANT") | Q6: =COUNTIFS('Photo Review'!$J$2:$J$403,A6,'Photo Review'!$S$2:$S$403,"?*")
A7: 2369 | B7: SL00170 | C7: MUJAHID . | D7: GTR02 | E7: GURUGRAM | F7: PUNEET WADHWA | G7: 350602 | H7: 46311 | I7: 46311 | J7: 432 | K7: =IFERROR(INDEX('Photo Review'!$W$2:$W$403,MATCH($A7&"|START",'Photo Review'!$Z$2:$Z$403,0)),"Photo missing / not downloaded") | L7: =IFERROR(INDEX('Photo Review'!$W$2:$W$403,MATCH($A7&"|END",'Photo Review'!$Z$2:$Z$403,0)),"Photo missing / not downloaded") | M7: =IF(AND(K7="Timestamp + Location",L7="Timestamp + Location"),"Compliant","NON-COMPLIANT") | N7: 7850 | O7: 7993 | P7: 143 | Q7: =COUNTIFS('Photo Review'!$J$2:$J$403,A7,'Photo Review'!$S$2:$S$403,"?*")
A8: 3029 | B8: SL00170 | C8: MUJAHID . | D8: GTR02 | E8: GURUGRAM | F8: PUNEET WADHWA | G8: 351135 | H8: 46312 | I8: 46312 | J8: 336 | K8: =IFERROR(INDEX('Photo Review'!$W$2:$W$403,MATCH($A8&"|START",'Photo Review'!$Z$2:$Z$403,0)),"Photo missing / not downloaded") | L8: =IFERROR(INDEX('Photo Review'!$W$2:$W$403,MATCH($A8&"|END",'Photo Review'!$Z$2:$Z$403,0)),"Photo missing / not downloaded") | M8: =IF(AND(K8="Timestamp + Location",L8="Timestamp + Location"),"Compliant","NON-COMPLIANT") | Q8: =COUNTIFS('Photo Review'!$J$2:$J$403,A8,'Photo Review'!$S$2:$S$403,"?*")
A9: 3215 | B9: SL01707 | C9: PANKAJ KUMAR PANDEY | D9: GTR03 A | E9: FAIZABAD | F9: PRADEEP KUMAR | G9: 351276 | H9: 46310 | I9: 46313 | J9: 124 | K9: =IFERROR(INDEX('Photo Review'!$W$2:$W$403,MATCH($A9&"|START",'Photo Review'!$Z$2:$Z$403,0)),"Photo missing / not downloaded") | L9: =IFERROR(INDEX('Photo Review'!$W$2:$W$403,MATCH($A9&"|END",'Photo Review'!$Z$2:$Z$403,0)),"Photo missing / not downloaded") | M9: =IF(AND(K9="Timestamp + Location",L9="Timestamp + Location"),"Compliant","NON-COMPLIANT") | Q9: =COUNTIFS('Photo Review'!$J$2:$J$403,A9,'Photo Review'!$S$2:$S$403,"?*")
A10: 149 | B10: SL01966 | C10: SHASHIDHAR NAIR | D10: GTR08 | E10: BANGALORE | F10: GANGADHARAM K | G10: 348187 | H10: 46307 | I10: 46307 | J10: 179.2 | K10: =IFERROR(INDEX('Photo Review'!$W$2:$W$403,MATCH($A10&"|START",'Photo Review'!$Z$2:$Z$403,0)),"Photo missing / not downloaded") | L10: =IFERROR(INDEX('Photo Review'!$W$2:$W$403,MATCH($A10&"|END",'Photo Review'!$Z$2:$Z$403,0)),"Photo missing / not downloaded") | M10: =IF(AND(K10="Timestamp + Location",L10="Timestamp + Location"),"Compliant","NON-COMPLIANT") | N10: 4643.7 | O10: 4648.3 | P10: 4.6 | Q10: =COUNTIFS('Photo Review'!$J$2:$J$403,A10,'Photo Review'!$S$2:$S$403,"?*")
A11: 524 | B11: SL01966 | C11: SHASHIDHAR NAIR | D11: GTR08 | E11: BANGALORE | F11: GANGADHARAM K | G11: 348804 | H11: 46308 | I11: 46308 | J11: 132 | K11: =IFERROR(INDEX('Photo Review'!$W$2:$W$403,MATCH($A11&"|START",'Photo Review'!$Z$2:$Z$403,0)),"Photo missing / not downloaded") | L11: =IFERROR(INDEX('Photo Review'!$W$2:$W$403,MATCH($A11&"|END",'Photo Review'!$Z$2:$Z$403,0)),"Photo missing / not downloaded") | M11: =IF(AND(K11="Timestamp + Location",L11="Timestamp + Location"),"Compliant","NON-COMPLIANT") | N11: 4648.8 | O11: 4652.1 | P11: 3.3 | Q11: =COUNTIFS('Photo Review'!$J$2:$J$403,A11,'Photo Review'!$S$2:$S$403,"?*")
A12: 908 | B12: SL01966 | C12: SHASHIDHAR NAIR | D12: GTR08 | E12: BANGALORE | F12: GANGADHARAM K | G12: 349255 | H12: 46309 | I12: 46309 | J12: 245.2 | K12: =IFERROR(INDEX('Photo Review'!$W$2:$W$403,MATCH($A12&"|START",'Photo Review'!$Z$2:$Z$403,0)),"Photo missing / not downloaded") | L12: =IFERROR(INDEX('Photo Review'!$W$2:$W$403,MATCH($A12&"|END",'Photo Review'!$Z$2:$Z$403,0)),"Photo missing / not downloaded") | M12: =IF(AND(K12="Timestamp + Location",L12="Timestamp + Location"),"Compliant","NON-COMPLIANT") | N12: 4652.1 | O12: 4658.2 | P12: 6.1 | Q12: =COUNTIFS('Photo Review'!$J$2:$J$403,A12,'Photo Review'!$S$2:$S$403,"?*")
A13: 1461 | B13: SL01966 | C13: SHASHIDHAR NAIR | D13: GTR08 | E13: BANGALORE | F13: GANGADHARAM K | G13: 349796 | H13: 46310 | I13: 46310 | J13: 151.2 | K13: =IFERROR(INDEX('Photo Review'!$W$2:$W$403,MATCH($A13&"|START",'Photo Review'!$Z$2:$Z$403,0)),"Photo missing / not downloaded") | L13: =IFERROR(INDEX('Photo Review'!$W$2:$W$403,MATCH($A13&"|END",'Photo Review'!$Z$2:$Z$403,0)),"Photo missing / not downloaded") | M13: =IF(AND(K13="Timestamp + Location",L13="Timestamp + Location"),"Compliant","NON-COMPLIANT") | N13: 4658.2 | O13: 4662 | P13: 3.8 | Q13: =COUNTIFS('Photo Review'!$J$2:$J$403,A13,'Photo Review'!$S$2:$S$403,"?*")
A14: 2130 | B14: SL01966 | C14: SHASHIDHAR NAIR | D14: GTR08 | E14: BANGALORE | F14: GANGADHARAM K | G14: 350390 | H14: 46311 | I14: 46311 | J14: 135.6 | K14: =IFERROR(INDEX('Photo Review'!$W$2:$W$403,MATCH($A14&"|START",'Photo Review'!$Z$2:$Z$403,0)),"Photo missing / not downloaded") | L14: =IFERROR(INDEX('Photo Review'!$W$2:$W$403,MATCH($A14&"|END",'Photo Review'!$Z$2:$Z$403,0)),"Photo missing / not downloaded") | M14: =IF(AND(K14="Timestamp + Location",L14="Timestamp + Location"),"Compliant","NON-COMPLIANT") | N14: 46620.2 | O14: 46654.1 | P14: 33.9 | Q14: =COUNTIFS('Photo Review'!$J$2:$J$403,A14,'Photo Review'!$S$2:$S$403,"?*")
A15: 2808 | B15: SL01966 | C15: SHASHIDHAR NAIR | D15: GTR08 | E15: BANGALORE | F15: GANGADHARAM K | G15: 350949 | H15: 46312 | I15: 46312 | J15: 150.8 | K15: =IFERROR(INDEX('Photo Review'!$W$2:$W$403,MATCH($A15&"|START",'Photo Review'!$Z$2:$Z$403,0)),"Photo missing / not downloaded") | L15: =IFERROR(INDEX('Photo Review'!$W$2:$W$403,MATCH($A15&"|END",'Photo Review'!$Z$2:$Z$403,0)),"Photo missing / not downloaded") | M15: =IF(AND(K15="Timestamp + Location",L15="Timestamp + Location"),"Compliant","NON-COMPLIANT") | N15: 4665.4 | O15: 4669.2 | P15: 3.8 | Q15: =COUNTIFS('Photo Review'!$J$2:$J$403,A15,'Photo Review'!$S$2:$S$403,"?*")
A16: 1237 | B16: SL02068 | C16: ZEVER FARNONDES | D16: GTR08 | E16: PANJIM | F16: MANOHAR KUMAR JHA | G16: 349587 | H16: 46307 | I16: 46309 | J16: 140 | K16: =IFERROR(INDEX('Photo Review'!$W$2:$W$403,MATCH($A16&"|START",'Photo Review'!$Z$2:$Z$403,0)),"Photo missing / not downloaded") | L16: =IFERROR(INDEX('Photo Review'!$W$2:$W$403,MATCH($A16&"|END",'Photo Review'!$Z$2:$Z$403,0)),"Photo missing / not downloaded") | M16: =IF(AND(K16="Timestamp + Location",L16="Timestamp + Location"),"Compliant","NON-COMPLIANT") | Q16: =COUNTIFS('Photo Review'!$J$2:$J$403,A16,'Photo Review'!$S$2:$S$403,"?*")
A17: 1238 | B17: SL02068 | C17: ZEVER FARNONDES | D17: GTR08 | E17: PANJIM | F17: MANOHAR KUMAR JHA | G17: 349588 | H17: 46308 | I17: 46309 | J17: 108 | K17: =IFERROR(INDEX('Photo Review'!$W$2:$W$403,MATCH($A17&"|START",'Photo Review'!$Z$2:$Z$403,0)),"Photo missing / not downloaded") | L17: =IFERROR(INDEX('Photo Review'!$W$2:$W$403,MATCH($A17&"|END",'Photo Review'!$Z$2:$Z$403,0)),"Photo missing / not downloaded") | M17: =IF(AND(K17="Timestamp + Location",L17="Timestamp + Location"),"Compliant","NON-COMPLIANT") | Q17: =COUNTIFS('Photo Review'!$J$2:$J$403,A17,'Photo Review'!$S$2:$S$403,"?*")
A18: 1244 | B18: SL02068 | C18: ZEVER FARNONDES | D18: GTR08 | E18: PANJIM | F18: MANOHAR KUMAR JHA | G18: 328946 | H18: 46309 | I18: 46309 | J18: 96 | K18: =IFERROR(INDEX('Photo Review'!$W$2:$W$403,MATCH($A18&"|START",'Photo Review'!$Z$2:$Z$403,0)),"Photo missing / not downloaded") | L18: =IFERROR(INDEX('Photo Review'!$W$2:$W$403,MATCH($A18&"|END",'Photo Review'!$Z$2:$Z$403,0)),"Photo missing / not downloaded") | M18: =IF(AND(K18="Timestamp + Location",L18="Timestamp + Location"),"Compliant","NON-COMPLIANT") | Q18: =COUNTIFS('Photo Review'!$J$2:$J$403,A18,'Photo Review'!$S$2:$S$403,"?*")
A19: 3665 | B19: SL02068 | C19: ZEVER FARNONDES | D19: GTR08 | E19: PANJIM | F19: MANOHAR KUMAR JHA | G19: 351840 | H19: 46310 | I19: 46314 | J19: 76 | K19: =IFERROR(INDEX('Photo Review'!$W$2:$W$403,MATCH($A19&"|START",'Photo Review'!$Z$2:$Z$403,0)),"Photo missing / not downloaded") | L19: =IFERROR(INDEX('Photo Review'!$W$2:$W$403,MATCH($A19&"|END",'Photo Review'!$Z$2:$Z$403,0)),"Photo missing / not downloaded") | M19: =IF(AND(K19="Timestamp + Location",L19="Timestamp + Location"),"Compliant","NON-COMPLIANT") | Q19: =COUNTIFS('Photo Review'!$J$2:$J$403,A19,'Photo Review'!$S$2:$S$403,"?*")
A20: 3669 | B20: SL02068 | C20: ZEVER FARNONDES | D20: GTR08 | E20: PANJIM | F20: MANOHAR KUMAR JHA | G20: 351843 | H20: 46311 | I20: 46314 | J20: 88 | K20: =IFERROR(INDEX('Photo Review'!$W$2:$W$403,MATCH($A20&"|START",'Photo Review'!$Z$2:$Z$403,0)),"Photo missing / not downloaded") | L20: =IFERROR(INDEX('Photo Review'!$W$2:$W$403,MATCH($A20&"|END",'Photo Review'!$Z$2:$Z$403,0)),"Photo missing / not downloaded") | M20: =IF(AND(K20="Timestamp + Location",L20="Timestamp + Location"),"Compliant","NON-COMPLIANT") | N20: 34209 | O20: 34266.8 | P20: 57.8 | Q20: =COUNTIFS('Photo Review'!$J$2:$J$403,A20,'Photo Review'!$S$2:$S$403,"?*")
A21: 3672 | B21: SL02068 | C21: ZEVER FARNONDES | D21: GTR08 | E21: PANJIM | F21: MANOHAR KUMAR JHA | G21: 351847 | H21: 46312 | I21: 46314 | J21: 84 | K21: =IFERROR(INDEX('Photo Review'!$W$2:$W$403,MATCH($A21&"|START",'Photo Review'!$Z$2:$Z$403,0)),"Photo missing / not downloaded") | L21: =IFERROR(INDEX('Photo Review'!$W$2:$W$403,MATCH($A21&"|END",'Photo Review'!$Z$2:$Z$403,0)),"Photo missing / not downloaded") | M21: =IF(AND(K21="Timestamp + Location",L21="Timestamp + Location"),"Compliant","NON-COMPLIANT") | Q21: =COUNTIFS('Photo Review'!$J$2:$J$403,A21,'Photo Review'!$S$2:$S$403,"?*")
A22: 1113 | B22: SL02286 | C22: AMIT KUMAR SINGH | D22: GTR03 A | E22: Lucknow | F22: SAURABH JAISWAL | G22: 349462 | H22: 46307 | I22: 46309 | J22: 128 | K22: =IFERROR(INDEX('Photo Review'!$W$2:$W$403,MATCH($A22&"|START",'Photo Review'!$Z$2:$Z$403,0)),"Photo missing / not downloaded") | L22: =IFERROR(INDEX('Photo Review'!$W$2:$W$403,MATCH($A22&"|END",'Photo Review'!$Z$2:$Z$403,0)),"Photo missing / not downloaded") | M22: =IF(AND(K22="Timestamp + Location",L22="Timestamp + Location"),"Compliant","NON-COMPLIANT") | Q22: =COUNTIFS('Photo Review'!$J$2:$J$403,A22,'Photo Review'!$S$2:$S$403,"?*")
A23: 1149 | B23: SL02286 | C23: AMIT KUMAR SINGH | D23: GTR03 A | E23: Lucknow | F23: SAURABH JAISWAL | G23: 349500 | H23: 46309 | I23: 46309 | J23: 128 | K23: =IFERROR(INDEX('Photo Review'!$W$2:$W$403,MATCH($A23&"|START",'Photo Review'!$Z$2:$Z$403,0)),"Photo missing / not downloaded") | L23: =IFERROR(INDEX('Photo Review'!$W$2:$W$403,MATCH($A23&"|END",'Photo Review'!$Z$2:$Z$403,0)),"Photo missing / not downloaded") | M23: =IF(AND(K23="Timestamp + Location",L23="Timestamp + Location"),"Compliant","NON-COMPLIANT") | N23: 6057.6 | O23: 6064.3 | P23: 6.7 | Q23: =COUNTIFS('Photo Review'!$J$2:$J$403,A23,'Photo Review'!$S$2:$S$403,"?*")
A24: 1678 | B24: SL02286 | C24: AMIT KUMAR SINGH | D24: GTR03 A | E24: Lucknow | F24: SAURABH JAISWAL | G24: 349989 | H24: 46310 | I24: 46310 | J24: 184 | K24: =IFERROR(INDEX('Photo Review'!$W$2:$W$403,MATCH($A24&"|START",'Photo Review'!$Z$2:$Z$403,0)),"Photo missing / not downloaded") | L24: =IFERROR(INDEX('Photo Review'!$W$2:$W$403,MATCH($A24&"|END",'Photo Review'!$Z$2:$Z$403,0)),"Photo missing / not downloaded") | M24: =IF(AND(K24="Timestamp + Location",L24="Timestamp + Location"),"Compliant","NON-COMPLIANT") | N24: 6064.3 | O24: 6072.4 | P24: 8.1 | Q24: =COUNTIFS('Photo Review'!$J$2:$J$403,A24,'Photo Review'!$S$2:$S$403,"?*")
A25: 2293 | B25: SL02286 | C25: AMIT KUMAR SINGH | D25: GTR03 A | E25: Lucknow | F25: SAURABH JAISWAL | G25: 350537 | H25: 46311 | I25: 46311 | J25: 132 | K25: =IFERROR(INDEX('Photo Review'!$W$2:$W$403,MATCH($A25&"|START",'Photo Review'!$Z$2:$Z$403,0)),"Photo missing / not downloaded") | L25: =IFERROR(INDEX('Photo Review'!$W$2:$W$403,MATCH($A25&"|END",'Photo Review'!$Z$2:$Z$403,0)),"Photo missing / not downloaded") | M25: =IF(AND(K25="Timestamp + Location",L25="Timestamp + Location"),"Compliant","NON-COMPLIANT") | N25: 6072.4 | O25: 6079.2 | P25: 6.8 | Q25: =COUNTIFS('Photo Review'!$J$2:$J$403,A25,'Photo Review'!$S$2:$S$403,"?*")
A26: 1782 | B26: SL02458 | C26: SURESH KUMAR JENA | D26: GTR05 | E26: cuttack | F26: UMA SANKAR PATTANAIK | G26: 350082 | H26: 46310 | I26: 46310 | J26: 276 | K26: =IFERROR(INDEX('Photo Review'!$W$2:$W$403,MATCH($A26&"|START",'Photo Review'!$Z$2:$Z$403,0)),"Photo missing / not downloaded") | L26: =IFERROR(INDEX('Photo Review'!$W$2:$W$403,MATCH($A26&"|END",'Photo Review'!$Z$2:$Z$403,0)),"Photo missing / not downloaded") | M26: =IF(AND(K26="Timestamp + Location",L26="Timestamp + Location"),"Compliant","NON-COMPLIANT") | Q26: =COUNTIFS('Photo Review'!$J$2:$J$403,A26,'Photo Review'!$S$2:$S$403,"?*")
A27: 3646 | B27: SL02480 | C27: B Venkataiah | D27: South | E27: Hyderabad | F27: K.Purushotham | G27: 351812 | H27: 46311 | I27: 46314 | J27: 100 | K27: =IFERROR(INDEX('Photo Review'!$W$2:$W$403,MATCH($A27&"|START",'Photo Review'!$Z$2:$Z$403,0)),"Photo missing / not downloaded") | L27: =IFERROR(INDEX('Photo Review'!$W$2:$W$403,MATCH($A27&"|END",'Photo Review'!$Z$2:$Z$403,0)),"Photo missing / not downloaded") | M27: =IF(AND(K27="Timestamp + Location",L27="Timestamp + Location"),"Compliant","NON-COMPLIANT") | N27: 1000 | O27: 1000 | P27: 0 | Q27: =COUNTIFS('Photo Review'!$J$2:$J$403,A27,'Photo Review'!$S$2:$S$403,"?*")
A28: 3656 | B28: SL02480 | C28: B Venkataiah | D28: South | E28: Hyderabad | F28: K.Purushotham | G28: 351825 | H28: 46312 | I28: 46314 | J28: 40 | K28: =IFERROR(INDEX('Photo Review'!$W$2:$W$403,MATCH($A28&"|START",'Photo Review'!$Z$2:$Z$403,0)),"Photo missing / not downloaded") | L28: =IFERROR(INDEX('Photo Review'!$W$2:$W$403,MATCH($A28&"|END",'Photo Review'!$Z$2:$Z$403,0)),"Photo missing / not downloaded") | M28: =IF(AND(K28="Timestamp + Location",L28="Timestamp + Location"),"Compliant","NON-COMPLIANT") | N28: 1000 | O28: 1000 | P28: 0 | Q28: =COUNTIFS('Photo Review'!$J$2:$J$403,A28,'Photo Review'!$S$2:$S$403,"?*")
A29: 217 | B29: SL02611 | C29: Mahesh Kumar Gujjari | D29: South | E29: HYDERABAD | F29: K.Purushotham | G29: 348297 | H29: 46307 | I29: 46307 | J29: 168 | K29: =IFERROR(INDEX('Photo Review'!$W$2:$W$403,MATCH($A29&"|START",'Photo Review'!$Z$2:$Z$403,0)),"Photo missing / not downloaded") | L29: =IFERROR(INDEX('Photo Review'!$W$2:$W$403,MATCH($A29&"|END",'Photo Review'!$Z$2:$Z$403,0)),"Photo missing / not downloaded") | M29: =IF(AND(K29="Timestamp + Location",L29="Timestamp + Location"),"Compliant","NON-COMPLIANT") | N29: 8030 | O29: 8037.7 | P29: 7.7 | Q29: =COUNTIFS('Photo Review'!$J$2:$J$403,A29,'Photo Review'!$S$2:$S$403,"?*")
A30: 625 | B30: SL02611 | C30: Mahesh Kumar Gujjari | D30: South | E30: HYDERABAD | F30: K.Purushotham | G30: 348925 | H30: 46308 | I30: 46308 | J30: 244 | K30: =IFERROR(INDEX('Photo Review'!$W$2:$W$403,MATCH($A30&"|START",'Photo Review'!$Z$2:$Z$403,0)),"Photo missing / not downloaded") | L30: =IFERROR(INDEX('Photo Review'!$W$2:$W$403,MATCH($A30&"|END",'Photo Review'!$Z$2:$Z$403,0)),"Photo missing / not downloaded") | M30: =IF(AND(K30="Timestamp + Location",L30="Timestamp + Location"),"Compliant","NON-COMPLIANT") | N30: 8037.9 | O30: 8047.5 | P30: 9.6 | Q30: =COUNTIFS('Photo Review'!$J$2:$J$403,A30,'Photo Review'!$S$2:$S$403,"?*")
A31: 1423 | B31: SL02611 | C31: Mahesh Kumar Gujjari | D31: South | E31: HYDERABAD | F31: K.Purushotham | G31: 349766 | H31: 46310 | I31: 46310 | J31: 64 | K31: =IFERROR(INDEX('Photo Review'!$W$2:$W$403,MATCH($A31&"|START",'Photo Review'!$Z$2:$Z$403,0)),"Photo missing / not downloaded") | L31: =IFERROR(INDEX('Photo Review'!$W$2:$W$403,MATCH($A31&"|END",'Photo Review'!$Z$2:$Z$403,0)),"Photo missing / not downloaded") | M31: =IF(AND(K31="Timestamp + Location",L31="Timestamp + Location"),"Compliant","NON-COMPLIANT") | N31: 8049.8 | O31: 8054.9 | P31: 5.1 | Q31: =COUNTIFS('Photo Review'!$J$2:$J$403,A31,'Photo Review'!$S$2:$S$403,"?*")
A32: 3476 | B32: SL02670 | C32: RAMAKANTA SAHU | D32: GTR05 | E32: BALANGIRI | F32: UMA SANKAR PATTANAIK | G32: 351558 | H32: 46311 | I32: 46314 | J32: 584 | K32: =IFERROR(INDEX('Photo Review'!$W$2:$W$403,MATCH($A32&"|START",'Photo Review'!$Z$2:$Z$403,0)),"Photo missing / not downloaded") | L32: =IFERROR(INDEX('Photo Review'!$W$2:$W$403,MATCH($A32&"|END",'Photo Review'!$Z$2:$Z$403,0)),"Photo missing / not downloaded") | M32: =IF(AND(K32="Timestamp + Location",L32="Timestamp + Location"),"Compliant","NON-COMPLIANT") | N32: 16540 | O32: 16554.7 | P32: 14.7 | Q32: =COUNTIFS('Photo Review'!$J$2:$J$403,A32,'Photo Review'!$S$2:$S$403,"?*")
A33: 3900 | B33: SL02671 | C33: IBRAR ALAM | D33: GTR02 | E33: EAST DELHI | F33: RAHUL GAUTAM | G33: 352100 | H33: 46312 | I33: 46316 | J33: 64 | K33: =IFERROR(INDEX('Photo Review'!$W$2:$W$403,MATCH($A33&"|START",'Photo Review'!$Z$2:$Z$403,0)),"Photo missing / not downloaded") | L33: =IFERROR(INDEX('Photo Review'!$W$2:$W$403,MATCH($A33&"|END",'Photo Review'!$Z$2:$Z$403,0)),"Photo missing / not downloaded") | M33: =IF(AND(K33="Timestamp + Location",L33="Timestamp + Location"),"Compliant","NON-COMPLIANT") | N33: 49322.9 | O33: 49373.9 | P33: 51 | Q33: =COUNTIFS('Photo Review'!$J$2:$J$403,A33,'Photo Review'!$S$2:$S$403,"?*")
A34: 232 | B34: SL02826 | C34: KIRAN KUMAR NAYAK | D34: GTR08 | E34: BANGALORE | F34: GANGADHARAM K | G34: 348314 | H34: 46307 | I34: 46307 | J34: 80 | K34: =IFERROR(INDEX('Photo Review'!$W$2:$W$403,MATCH($A34&"|START",'Photo Review'!$Z$2:$Z$403,0)),"Photo missing / not downloaded") | L34: =IFERROR(INDEX('Photo Review'!$W$2:$W$403,MATCH($A34&"|END",'Photo Review'!$Z$2:$Z$403,0)),"Photo missing / not downloaded") | M34: =IF(AND(K34="Timestamp + Location",L34="Timestamp + Location"),"Compliant","NON-COMPLIANT") | Q34: =COUNTIFS('Photo Review'!$J$2:$J$403,A34,'Photo Review'!$S$2:$S$403,"?*")
A35: 346 | B35: SL02826 | C35: KIRAN KUMAR NAYAK | D35: GTR08 | E35: BANGALORE | F35: GANGADHARAM K | G35: 348590 | H35: 46308 | I35: 46308 | J35: 72 | K35: =IFERROR(INDEX('Photo Review'!$W$2:$W$403,MATCH($A35&"|START",'Photo Review'!$Z$2:$Z$403,0)),"Photo missing / not downloaded") | L35: =IFERROR(INDEX('Photo Review'!$W$2:$W$403,MATCH($A35&"|END",'Photo Review'!$Z$2:$Z$403,0)),"Photo missing / not downloaded") | M35: =IF(AND(K35="Timestamp + Location",L35="Timestamp + Location"),"Compliant","NON-COMPLIANT") | Q35: =COUNTIFS('Photo Review'!$J$2:$J$403,A35,'Photo Review'!$S$2:$S$403,"?*")
A36: 2339 | B36: SL02826 | C36: KIRAN KUMAR NAYAK | D36: GTR08 | E36: BANGALORE | F36: GANGADHARAM K | G36: 350572 | H36: 46309 | I36: 46311 | J36: 60 | K36: =IFERROR(INDEX('Photo Review'!$W$2:$W$403,MATCH($A36&"|START",'Photo Review'!$Z$2:$Z$403,0)),"Photo missing / not downloaded") | L36: =IFERROR(INDEX('Photo Review'!$W$2:$W$403,MATCH($A36&"|END",'Photo Review'!$Z$2:$Z$403,0)),"Photo missing / not downloaded") | M36: =IF(AND(K36="Timestamp + Location",L36="Timestamp + Location"),"Compliant","NON-COMPLIANT") | Q36: =COUNTIFS('Photo Review'!$J$2:$J$403,A36,'Photo Review'!$S$2:$S$403,"?*")
A37: 2349 | B37: SL02826 | C37: KIRAN KUMAR NAYAK | D37: GTR08 | E37: BANGALORE | F37: GANGADHARAM K | G37: 350585 | H37: 46310 | I37: 46311 | J37: 92 | K37: =IFERROR(INDEX('Photo Review'!$W$2:$W$403,MATCH($A37&"|START",'Photo Review'!$Z$2:$Z$403,0)),"Photo missing / not downloaded") | L37: =IFERROR(INDEX('Photo Review'!$W$2:$W$403,MATCH($A37&"|END",'Photo Review'!$Z$2:$Z$403,0)),"Photo missing / not downloaded") | M37: =IF(AND(K37="Timestamp + Location",L37="Timestamp + Location"),"Compliant","NON-COMPLIANT") | Q37: =COUNTIFS('Photo Review'!$J$2:$J$403,A37,'Photo Review'!$S$2:$S$403,"?*")
A38: 2333 | B38: SL02826 | C38: KIRAN KUMAR NAYAK | D38: GTR08 | E38: BANGALORE | F38: GANGADHARAM K | G38: 350566 | H38: 46311 | I38: 46311 | J38: 200 | K38: =IFERROR(INDEX('Photo Review'!$W$2:$W$403,MATCH($A38&"|START",'Photo Review'!$Z$2:$Z$403,0)),"Photo missing / not downloaded") | L38: =IFERROR(INDEX('Photo Review'!$W$2:$W$403,MATCH($A38&"|END",'Photo Review'!$Z$2:$Z$403,0)),"Photo missing / not downloaded") | M38: =IF(AND(K38="Timestamp + Location",L38="Timestamp + Location"),"Compliant","NON-COMPLIANT") | N38: 58854 | O38: 58939.4 | P38: 85.4 | Q38: =COUNTIFS('Photo Review'!$J$2:$J$403,A38,'Photo Review'!$S$2:$S$403,"?*")
A39: 3635 | B39: SL02930 | C39: A. SURESH GOUD | D39: GTR07 | E39: Jadcherla | F39: B BHASKAR | G39: 351802 | H39: 46312 | I39: 46314 | J39: 192 | K39: =IFERROR(INDEX('Photo Review'!$W$2:$W$403,MATCH($A39&"|START",'Photo Review'!$Z$2:$Z$403,0)),"Photo missing / not downloaded") | L39: =IFERROR(INDEX('Photo Review'!$W$2:$W$403,MATCH($A39&"|END",'Photo Review'!$Z$2:$Z$403,0)),"Photo missing / not downloaded") | M39: =IF(AND(K39="Timestamp + Location",L39="Timestamp + Location"),"Compliant","NON-COMPLIANT") | N39: 37427 | O39: 37475.8 | P39: 48.8 | Q39: =COUNTIFS('Photo Review'!$J$2:$J$403,A39,'Photo Review'!$S$2:$S$403,"?*")
A40: 794 | B40: SL03071 | C40: Bhavana Yadav | D40: West | E40: RAIPUR | F40: POKHRAJ KUMAR SAHU | G40: 349124 | H40: 46307 | I40: 46309 | J40: 264 | K40: =IFERROR(INDEX('Photo Review'!$W$2:$W$403,MATCH($A40&"|START",'Photo Review'!$Z$2:$Z$403,0)),"Photo missing / not downloaded") | L40: =IFERROR(INDEX('Photo Review'!$W$2:$W$403,MATCH($A40&"|END",'Photo Review'!$Z$2:$Z$403,0)),"Photo missing / not downloaded") | M40: =IF(AND(K40="Timestamp + Location",L40="Timestamp + Location"),"Compliant","NON-COMPLIANT") | N40: 5259.9 | O40: 5270 | P40: 10.1 | Q40: =COUNTIFS('Photo Review'!$J$2:$J$403,A40,'Photo Review'!$S$2:$S$403,"?*")
...

Sheet Photo Review
A1: Photo # | B1: Employee_code | C1: User_Name | D1: Designation | E1: Zone | F1: HQ | G1: L1 Approver | H1: Claim_Id | I1: Claim_Date | J1: Claim Key | K1: Side | L1: Claim_Amount (₹) | M1: Photo | N1: App Result | O1: Stamp Date(s) | P1: Stamp Time | Q1: Stamp GPS / App | R1: Odometer (OCR) | S1: Red Flags | T1: Flag Level | U1: Check Priority | V1: HR Check | W1: Final Result | X1: Compliant? | Y1: Photo Link | Z1: Lookup Key | AA1: Text read from photo
A2: 1 | B2: SL00147 | C2: Girish Kahar | D2: SO | E2: West | F2: VADODARA | G2: NAVEEN N ANCHAN | H2: 350983 | I2: 46312 | J2: 2847 | K2: START | L2: 472 | N2: Timestamp + Location | O2: 17-Oct-2026 | P2: 08:06 | R2: 329576 | W2: =IF(V2="Wrong - photo HAS timestamp + location","Timestamp + Location",IF(V2="Wrong - photo has NO stamp","No stamp",N2)) | X2: =IF(W2="Timestamp + Location","Yes","No") | Y2: Open photo | Z2: =J2&"|"&K2 | AA2: 60 | 80 | 329576 | 17 0ct 2026 08:06:53 | Kevdabaug | Vadodara | Gujarat | 17 0ct 2026 08:06:53 | Kevdabaug | Vadodara | Gujarat
A3: 2 | B3: SL00147 | C3: Girish Kahar | D3: SO | E3: West | F3: VADODARA | G3: NAVEEN N ANCHAN | H3: 350983 | I3: 46312 | J3: 2847 | K3: END | L3: 472 | N3: Timestamp + Location | O3: 17-Oct-2026 | P3: 19:33 | R3: 33708 | U3: 3 - Random sample (stamped) | W3: =IF(V3="Wrong - photo HAS timestamp + location","Timestamp + Location",IF(V3="Wrong - photo has NO stamp","No stamp",N3)) | X3: =IF(W3="Timestamp + Location","Yes","No") | Y3: Open photo | Z3: =J3&"|"&K3 | AA3: 5O | 80 | Ailill, | 33708 | 17 0ct 2026 19:33:36 | 1780 Navapura Road | Navapura | Vadodara | Gujarat | 17 0ct 2026 19:33:36 | 1780 Navapura Road | Navapura | Vadodara | Gujarat
A4: 3 | B4: SL00170 | C4: MUJAHID . | D4: SSO | E4: GTR02 | F4: GURUGRAM | G4: PUNEET WADHWA | H4: 348418 | I4: 46307 | J4: 279 | K4: START | L4: 516 | N4: No stamp | R4: 7516 | U4: 2 - Employee uses stamps elsewhere | W4: =IF(V4="Wrong - photo HAS timestamp + location","Timestamp + Location",IF(V4="Wrong - photo has NO stamp","No stamp",N4)) | X4: =IF(W4="Timestamp + Location","Yes","No") | Y4: Open photo | Z4: =J4&"|"&K4 | AA4: LOW | SIDE | EATTERY | STAND | IFE | km/L | ODO | 7516km | km/h | E | km/n | 面
